Workbook

Sheet Read Me
B2: Virginia Retail Sales Tax by Locality — 10-Year History, 20-Year Projection, and 1%-for-Schools Profile
B5: What this workbook contains
B6: Assumptions — statewide control totals and every growth lever the model uses. Yellow cells are yours to change.
B7: Historical FY16-FY25 — retail sales tax distributed to each of Virginia's 95 counties and 38 independent cities.
B8: Projection FY26-FY45 — 20-year forward projection of that distribution, locality by locality.
B9: Schools 1pct Profile — what a dedicated 1% school sales tax would raise in each locality, per year and cumulatively.
B11: Source data
B12: Virginia Department of Taxation, Annual Report, Table 4.3 'Local Sales Tax Distribution'.
B13: https://www.tax.virginia.gov/annual-reports
B14: FY2025 report (pp. 32-33) and FY2019 report (pp. 29-30) — full locality detail, entered as actuals (blue text).
B15: Table 4.1 of the FY2025 report — statewide Local Option totals for every year FY2016-FY2025, entered as actuals.
B16: Transcription check: the 133 locality figures sum to the published statewide totals within $5 (report rounding).
... B76: Status flags are only as good as the referendum filings behind them — update the Status column.

Sheet Assumptions
A1: Assumptions & Statewide Control Totals
A2: Yellow cells are inputs you can change. Everything downstream recalculates.
A4: Fiscal Year | B4: Statewide Local Option 1% ($) | C4: Ratio: Ed Share / Local Option | D4: Statewide State 1% Education Share ($) | E4: Statewide Total Distributed to Localities ($)
A5: 2016 | B5: 1188704000 | C5: =$C$8 -> 0.99807159 | D5: =B5*C5 -> 1.1864117e+09 | E5: =B5+D5 -> 2.3751157e+09
A6: 2017 | B6: 1213929000 | C6: =$C$8 -> 0.99807159 | D6: =B6*C6 -> 1.211588e+09 | E6: =B6+D6 -> 2.425517e+09
A7: 2018 | B7: 1243480000 | C7: =$C$8 -> 0.99807159 | D7: =B7*C7 -> 1.2410821e+09 | E7: =B7+D7 -> 2.4845621e+09
A8: 2019 | B8: 1292804000 | C8: =D8/B8 -> 0.99807159 | D8: 1290310945 | E8: =B8+D8 -> 2583114945
A9: 2020 | B9: 1358988000 | C9: =$C$8 -> 0.99807159 | D9: =B9*C9 -> 1.3563673e+09 | E9: =B9+D9 -> 2.7153553e+09
A10: 2021 | B10: 1477201000 | C10: =$C$8 -> 0.99807159 | D10: =B10*C10 -> 1.4743524e+09 | E10: =B10+D10 -> 2.9515534e+09
A11: 2022 | B11: 1662897000 | C11: =$C$8 -> 0.99807159 | D11: =B11*C11 -> 1.6596903e+09 | E11: =B11+D11 -> 3.3225873e+09
A12: 2023 | B12: 1770842000 | C12: =$C$8+($C$14-$C$8)*(A12-2022)/3 -> 0.94318166 | D12: =B12*C12 -> 1.6702257e+09 | E12: =B12+D12 -> 3.4410677e+09
A13: 2024 | B13: 1808583000 | C13: =$C$8+($C$14-$C$8)*(A13-2022)/3 -> 0.88829172 | D13: =B13*C13 -> 1.6065493e+09 | E13: =B13+D13 -> 3.4151323e+09
A14: 2025 | B14: 1876913000 | C14: =D14/B14 -> 0.83340179 | D14: 1564222650 | E14: =B14+D14 -> 3441135650
A15: Blue = published actual. FY2019 and FY2025 education-share figures are the Table 4.3 aggregates;
A16: Other years are modelled. The education share tracked Local Option almost 1:1 through FY2022, so the ratio is
A17: held flat to FY2022, then interpolated down to the FY2025 actual — the drop follows the Jan-2023 grocery tax repeal.
A18: Derived growth rates
A19: Statewide Local Option CAGR, FY2016-FY2025 (9 yrs) | B19: =(B14/B5)^(1/9)-1 -> 0.052061572
A20: Statewide Local Option CAGR, FY2019-FY2025 (6 yrs) | B20: =(B14/B8)^(1/6)-1 -> 0.064106859
A21: Statewide Total Distribution CAGR, FY2019-FY2025 | B21: =(E14/E8)^(1/6)-1 -> 0.04896181
A23: Projection levers (edit these)
A24: Baseline statewide growth rate applied to all localities | B24: =B19 -> 0.052061572 | C24: Defaults to the 9-year statewide CAGR. Lower to ~3.5% for a conservative case.
A25: Locality trend weight (0 = flat statewide rate, 1 = full local trend) | B25: 0.5 | C25: Damps extreme six-year local growth rates before running them out 20 years.
A26: Floor on any locality's growth rate | B26: 0 | C26: No locality is projected to shrink.
A27: Ceiling on any locality's growth rate | B27: 0.08 | C27: Caps runaway extrapolation for small, volatile localities.
A28: New school sales tax rate (percentage points) | B28: 0.01 | C28: The dedicated levy being modelled. Va. Code 58.1-605.1 caps this at 1%.
A29: Existing local option rate (basis for scaling) | B29: 0.01 | C29: Local Option is a 1% tax, so a new 1% levy on the same base yields ~the same amount.

Sheet Historical FY16-FY25
A1: Retail Sales Tax Distributed to Virginia Localities — FY2016 to FY2025
A2: Columns C-H are published actuals (blue). The FY2016-FY2025 series at right is modelled: actual statewide totals allocated on each locality's interpolated share. FY2019 and FY2025 reproduce the actuals exactly.
A4: Locality | B4: Type | C4: FY2019 Local Option ($) | D4: FY2025 Local Option ($) | E4: FY2019 State 1% Ed Share ($) | F4: FY2025 State 1% Ed Share ($) | G4: FY2019 Total ($) | H4: FY2025 Total ($) | I4: Local Option CAGR FY19-25 | J4: Total CAGR FY19-25 | K4: 2016 | L4: 2017 | M4: 2018 | N4: 2019 | O4: 2020 | P4: 2021 | Q4: 2022 | R4: 2023 | S4: 2024 | T4: 2025
A5: Accomack County | B5: County | C5: 4721028 | D5: 6374893 | E5: 4678123 | F5: 5447703 | G5: =C5+E5 -> 9399151 | H5: =D5+F5 -> 11822596 | I5: =IFERROR((D5/C5)^(1/6)-1,0) -> 0.051330799 | J5: =IFERROR((H5/G5)^(1/6)-1,0) -> 0.038972463 | K5: =($G5/Assumptions!$E$8+($H5/Assumptions!$E$14-$G5/Assumptions!$E$8)*(K$4-2019)/6)*INDEX(Assumptions!$E$5:$E$14,MATCH(K$4,Assumptions!$A$5:$A$14,0)) -> 8883406.5 | L5: =($G5/Assumptions!$E$8+($H5/Assumptions!$E$14-$G5/Assumptions!$E$8)*(L$4-2019)/6)*INDEX(Assumptions!$E$5:$E$14,MATCH(L$4,Assumptions!$A$5:$A$14,0)) -> 8989845.5 | M5: =($G5/Assumptions!$E$8+($H5/Assumptions!$E$14-$G5/Assumptions!$E$8)*(M$4-2019)/6)*INDEX(Assumptions!$E$5:$E$14,MATCH(M$4,Assumptions!$A$5:$A$14,0)) -> 9124617.7 | N5: =($G5/Assumptions!$E$8+($H5/Assumptions!$E$14-$G5/Assumptions!$E$8)*(N$4-2019)/6)*INDEX(Assumptions!$E$5:$E$14,MATCH(N$4,Assumptions!$A$5:$A$14,0)) -> 9399151 | O5: =($G5/Assumptions!$E$8+($H5/Assumptions!$E$14-$G5/Assumptions!$E$8)*(O$4-2019)/6)*INDEX(Assumptions!$E$5:$E$14,MATCH(O$4,Assumptions!$A$5:$A$14,0)) -> 9788453.2 | P5: =($G5/Assumptions!$E$8+($H5/Assumptions!$E$14-$G5/Assumptions!$E$8)*(P$4-2019)/6)*INDEX(Assumptions!$E$5:$E$14,MATCH(P$4,Assumptions!$A$5:$A$14,0)) -> 10540041 | Q5: =($G5/Assumptions!$E$8+($H5/Assumptions!$E$14-$G5/Assumptions!$E$8)*(Q$4-2019)/6)*INDEX(Assumptions!$E$5:$E$14,MATCH(Q$4,Assumptions!$A$5:$A$14,0)) -> 11752582 | R5: =($G5/Assumptions!$E$8+($H5/Assumptions!$E$14-$G5/Assumptions!$E$8)*(R$4-2019)/6)*INDEX(Assumptions!$E$5:$E$14,MATCH(R$4,Assumptions!$A$5:$A$14,0)) -> 12055233 | ... T5: =($G5/Assumptions!$E$8+($H5/Assumptions!$E$14-$G5/Assumptions!$E$8)*(T$4-2019)/6)*INDEX(Assumptions!$E$5:$E$14,MATCH(T$4,Assumptions!$A$5:$A$14,0)) -> 11822596
A6: Albemarle County | B6: County | C6: 17038808 | D6: 26225183 | E6: 15252442 | F6: 19212745 | G6: =C6+E6 -> 32291250 | H6: =D6+F6 -> 45437928 | I6: =IFERROR((D6/C6)^(1/6)-1,0) -> 0.074516824 | J6: =IFERROR((H6/G6)^(1/6)-1,0) -> 0.058576569 | K6: =($G6/Assumptions!$E$8+($H6/Assumptions!$E$14-$G6/Assumptions!$E$8)*(K$4-2019)/6)*INDEX(Assumptions!$E$5:$E$14,MATCH(K$4,Assumptions!$A$5:$A$14,0)) -> 28855691 | L6: =($G6/Assumptions!$E$8+($H6/Assumptions!$E$14-$G6/Assumptions!$E$8)*(L$4-2019)/6)*INDEX(Assumptions!$E$5:$E$14,MATCH(L$4,Assumptions!$A$5:$A$14,0)) -> 29752396 | M6: =($G6/Assumptions!$E$8+($H6/Assumptions!$E$14-$G6/Assumptions!$E$8)*(M$4-2019)/6)*INDEX(Assumptions!$E$5:$E$14,MATCH(M$4,Assumptions!$A$5:$A$14,0)) -> 30767958 | N6: =($G6/Assumptions!$E$8+($H6/Assumptions!$E$14-$G6/Assumptions!$E$8)*(N$4-2019)/6)*INDEX(Assumptions!$E$5:$E$14,MATCH(N$4,Assumptions!$A$5:$A$14,0)) -> 32291250 | O6: =($G6/Assumptions!$E$8+($H6/Assumptions!$E$14-$G6/Assumptions!$E$8)*(O$4-2019)/6)*INDEX(Assumptions!$E$5:$E$14,MATCH(O$4,Assumptions!$A$5:$A$14,0)) -> 34262724 | P6: =($G6/Assumptions!$E$8+($H6/Assumptions!$E$14-$G6/Assumptions!$E$8)*(P$4-2019)/6)*INDEX(Assumptions!$E$5:$E$14,MATCH(P$4,Assumptions!$A$5:$A$14,0)) -> 37589146 | Q6: =($G6/Assumptions!$E$8+($H6/Assumptions!$E$14-$G6/Assumptions!$E$8)*(Q$4-2019)/6)*INDEX(Assumptions!$E$5:$E$14,MATCH(Q$4,Assumptions!$A$5:$A$14,0)) -> 42703945 | R6: =($G6/Assumptions!$E$8+($H6/Assumptions!$E$14-$G6/Assumptions!$E$8)*(R$4-2019)/6)*INDEX(Assumptions!$E$5:$E$14,MATCH(R$4,Assumptions!$A$5:$A$14,0)) -> 44630163 | ... T6: =($G6/Assumptions!$E$8+($H6/Assumptions!$E$14-$G6/Assumptions!$E$8)*(T$4-2019)/6)*INDEX(Assumptions!$E$5:$E$14,MATCH(T$4,Assumptions!$A$5:$A$14,0)) -> 45437928
A7: Alleghany County | B7: County | C7: 958820 | D7: 1288843 | E7: 2224841 | F7: 2315274 | G7: =C7+E7 -> 3183661 | H7: =D7+F7 -> 3604117 | I7: =IFERROR((D7/C7)^(1/6)-1,0) -> 0.05053491 | J7: =IFERROR((H7/G7)^(1/6)-1,0) -> 0.020889359 | K7: =($G7/Assumptions!$E$8+($H7/Assumptions!$E$14-$G7/Assumptions!$E$8)*(K$4-2019)/6)*INDEX(Assumptions!$E$5:$E$14,MATCH(K$4,Assumptions!$A$5:$A$14,0)) -> 3147152.5 | L7: =($G7/Assumptions!$E$8+($H7/Assumptions!$E$14-$G7/Assumptions!$E$8)*(L$4-2019)/6)*INDEX(Assumptions!$E$5:$E$14,MATCH(L$4,Assumptions!$A$5:$A$14,0)) -> 3139099.1 | M7: =($G7/Assumptions!$E$8+($H7/Assumptions!$E$14-$G7/Assumptions!$E$8)*(M$4-2019)/6)*INDEX(Assumptions!$E$5:$E$14,MATCH(M$4,Assumptions!$A$5:$A$14,0)) -> 3138855.3 | N7: =($G7/Assumptions!$E$8+($H7/Assumptions!$E$14-$G7/Assumptions!$E$8)*(N$4-2019)/6)*INDEX(Assumptions!$E$5:$E$14,MATCH(N$4,Assumptions!$A$5:$A$14,0)) -> 3183661 | O7: =($G7/Assumptions!$E$8+($H7/Assumptions!$E$14-$G7/Assumptions!$E$8)*(O$4-2019)/6)*INDEX(Assumptions!$E$5:$E$14,MATCH(O$4,Assumptions!$A$5:$A$14,0)) -> 3262865.1 | P7: =($G7/Assumptions!$E$8+($H7/Assumptions!$E$14-$G7/Assumptions!$E$8)*(P$4-2019)/6)*INDEX(Assumptions!$E$5:$E$14,MATCH(P$4,Assumptions!$A$5:$A$14,0)) -> 3455620.5 | Q7: =($G7/Assumptions!$E$8+($H7/Assumptions!$E$14-$G7/Assumptions!$E$8)*(Q$4-2019)/6)*INDEX(Assumptions!$E$5:$E$14,MATCH(Q$4,Assumptions!$A$5:$A$14,0)) -> 3787503.2 | R7: =($G7/Assumptions!$E$8+($H7/Assumptions!$E$14-$G7/Assumptions!$E$8)*(R$4-2019)/6)*INDEX(Assumptions!$E$5:$E$14,MATCH(R$4,Assumptions!$A$5:$A$14,0)) -> 3816390 | ... T7: =($G7/Assumptions!$E$8+($H7/Assumptions!$E$14-$G7/Assumptions!$E$8)*(T$4-2019)/6)*INDEX(Assumptions!$E$5:$E$14,MATCH(T$4,Assumptions!$A$5:$A$14,0)) -> 3604117
A8: Amelia County | B8: County | C8: 821928 | D8: 1519698 | E8: 1893604 | F8: 2174286 | G8: =C8+E8 -> 2715532 | H8: =D8+F8 -> 3693984 | I8: =IFERROR((D8/C8)^(1/6)-1,0) -> 0.10786605 | J8: =IFERROR((H8/G8)^(1/6)-1,0) -> 0.052624193 | K8: =($G8/Assumptions!$E$8+($H8/Assumptions!$E$14-$G8/Assumptions!$E$8)*(K$4-2019)/6)*INDEX(Assumptions!$E$5:$E$14,MATCH(K$4,Assumptions!$A$5:$A$14,0)) -> 2470487.8 | L8: =($G8/Assumptions!$E$8+($H8/Assumptions!$E$14-$G8/Assumptions!$E$8)*(L$4-2019)/6)*INDEX(Assumptions!$E$5:$E$14,MATCH(L$4,Assumptions!$A$5:$A$14,0)) -> 2531893.8 | M8: =($G8/Assumptions!$E$8+($H8/Assumptions!$E$14-$G8/Assumptions!$E$8)*(M$4-2019)/6)*INDEX(Assumptions!$E$5:$E$14,MATCH(M$4,Assumptions!$A$5:$A$14,0)) -> 2602727.7 | N8: =($G8/Assumptions!$E$8+($H8/Assumptions!$E$14-$G8/Assumptions!$E$8)*(N$4-2019)/6)*INDEX(Assumptions!$E$5:$E$14,MATCH(N$4,Assumptions!$A$5:$A$14,0)) -> 2715532 | O8: =($G8/Assumptions!$E$8+($H8/Assumptions!$E$14-$G8/Assumptions!$E$8)*(O$4-2019)/6)*INDEX(Assumptions!$E$5:$E$14,MATCH(O$4,Assumptions!$A$5:$A$14,0)) -> 2864605.2 | P8: =($G8/Assumptions!$E$8+($H8/Assumptions!$E$14-$G8/Assumptions!$E$8)*(P$4-2019)/6)*INDEX(Assumptions!$E$5:$E$14,MATCH(P$4,Assumptions!$A$5:$A$14,0)) -> 3124714.4 | Q8: =($G8/Assumptions!$E$8+($H8/Assumptions!$E$14-$G8/Assumptions!$E$8)*(Q$4-2019)/6)*INDEX(Assumptions!$E$5:$E$14,MATCH(Q$4,Assumptions!$A$5:$A$14,0)) -> 3529818.2 | R8: =($G8/Assumptions!$E$8+($H8/Assumptions!$E$14-$G8/Assumptions!$E$8)*(R$4-2019)/6)*INDEX(Assumptions!$E$5:$E$14,MATCH(R$4,Assumptions!$A$5:$A$14,0)) -> 3668429.2 | ... T8: =($G8/Assumptions!$E$8+($H8/Assumptions!$E$14-$G8/Assumptions!$E$8)*(T$4-2019)/6)*INDEX(Assumptions!$E$5:$E$14,MATCH(T$4,Assumptions!$A$5:$A$14,0)) -> 3693984
A9: Amherst County | B9: County | C9: 2895601 | D9: 4726734 | E9: 4519031 | F9: 5146545 | G9: =C9+E9 -> 7414632 | H9: =D9+F9 -> 9873279 | I9: =IFERROR((D9/C9)^(1/6)-1,0) -> 0.085101609 | J9: =IFERROR((H9/G9)^(1/6)-1,0) -> 0.048886836 | K9: =($G9/Assumptions!$E$8+($H9/Assumptions!$E$14-$G9/Assumptions!$E$8)*(K$4-2019)/6)*INDEX(Assumptions!$E$5:$E$14,MATCH(K$4,Assumptions!$A$5:$A$14,0)) -> 6819047.8 | L9: =($G9/Assumptions!$E$8+($H9/Assumptions!$E$14-$G9/Assumptions!$E$8)*(L$4-2019)/6)*INDEX(Assumptions!$E$5:$E$14,MATCH(L$4,Assumptions!$A$5:$A$14,0)) -> 6963254.5 | M9: =($G9/Assumptions!$E$8+($H9/Assumptions!$E$14-$G9/Assumptions!$E$8)*(M$4-2019)/6)*INDEX(Assumptions!$E$5:$E$14,MATCH(M$4,Assumptions!$A$5:$A$14,0)) -> 7132253.2 | N9: =($G9/Assumptions!$E$8+($H9/Assumptions!$E$14-$G9/Assumptions!$E$8)*(N$4-2019)/6)*INDEX(Assumptions!$E$5:$E$14,MATCH(N$4,Assumptions!$A$5:$A$14,0)) -> 7414632 | O9: =($G9/Assumptions!$E$8+($H9/Assumptions!$E$14-$G9/Assumptions!$E$8)*(O$4-2019)/6)*INDEX(Assumptions!$E$5:$E$14,MATCH(O$4,Assumptions!$A$5:$A$14,0)) -> 7793660.8 | P9: =($G9/Assumptions!$E$8+($H9/Assumptions!$E$14-$G9/Assumptions!$E$8)*(P$4-2019)/6)*INDEX(Assumptions!$E$5:$E$14,MATCH(P$4,Assumptions!$A$5:$A$14,0)) -> 8470995.1 | Q9: =($G9/Assumptions!$E$8+($H9/Assumptions!$E$14-$G9/Assumptions!$E$8)*(Q$4-2019)/6)*INDEX(Assumptions!$E$5:$E$14,MATCH(Q$4,Assumptions!$A$5:$A$14,0)) -> 9535185.5 | R9: =($G9/Assumptions!$E$8+($H9/Assumptions!$E$14-$G9/Assumptions!$E$8)*(R$4-2019)/6)*INDEX(Assumptions!$E$5:$E$14,MATCH(R$4,Assumptions!$A$5:$A$14,0)) -> 9874495.7 | ... T9: =($G9/Assumptions!$E$8+($H9/Assumptions!$E$14-$G9/Assumptions!$E$8)*(T$4-2019)/6)*INDEX(Assumptions!$E$5:$E$14,MATCH(T$4,Assumptions!$A$5:$A$14,0)) -> 9873279
A10: Appomattox County | B10: County | C10: 1385301 | D10: 2192135 | E10: 2330903 | F10: 2958832 | G10: =C10+E10 -> 3716204 | H10: =D10+F10 -> 5150967 | I10: =IFERROR((D10/C10)^(1/6)-1,0) -> 0.079494726 | J10: =IFERROR((H10/G10)^(1/6)-1,0) -> 0.055921267 | K10: =($G10/Assumptions!$E$8+($H10/Assumptions!$E$14-$G10/Assumptions!$E$8)*(K$4-2019)/6)*INDEX(Assumptions!$E$5:$E$14,MATCH(K$4,Assumptions!$A$5:$A$14,0)) -> 3347816.6 | L10: =($G10/Assumptions!$E$8+($H10/Assumptions!$E$14-$G10/Assumptions!$E$8)*(L$4-2019)/6)*INDEX(Assumptions!$E$5:$E$14,MATCH(L$4,Assumptions!$A$5:$A$14,0)) -> 3442398 | M10: =($G10/Assumptions!$E$8+($H10/Assumptions!$E$14-$G10/Assumptions!$E$8)*(M$4-2019)/6)*INDEX(Assumptions!$E$5:$E$14,MATCH(M$4,Assumptions!$A$5:$A$14,0)) -> 3550308.9 | N10: =($G10/Assumptions!$E$8+($H10/Assumptions!$E$14-$G10/Assumptions!$E$8)*(N$4-2019)/6)*INDEX(Assumptions!$E$5:$E$14,MATCH(N$4,Assumptions!$A$5:$A$14,0)) -> 3716204 | O10: =($G10/Assumptions!$E$8+($H10/Assumptions!$E$14-$G10/Assumptions!$E$8)*(O$4-2019)/6)*INDEX(Assumptions!$E$5:$E$14,MATCH(O$4,Assumptions!$A$5:$A$14,0)) -> 3932803.4 | P10: =($G10/Assumptions!$E$8+($H10/Assumptions!$E$14-$G10/Assumptions!$E$8)*(P$4-2019)/6)*INDEX(Assumptions!$E$5:$E$14,MATCH(P$4,Assumptions!$A$5:$A$14,0)) -> 4303546.2 | Q10: =($G10/Assumptions!$E$8+($H10/Assumptions!$E$14-$G10/Assumptions!$E$8)*(Q$4-2019)/6)*INDEX(Assumptions!$E$5:$E$14,MATCH(Q$4,Assumptions!$A$5:$A$14,0)) -> 4876780.9 | R10: =($G10/Assumptions!$E$8+($H10/Assumptions!$E$14-$G10/Assumptions!$E$8)*(R$4-2019)/6)*INDEX(Assumptions!$E$5:$E$14,MATCH(R$4,Assumptions!$A$5:$A$14,0)) -> 5084076.7 | ... T10: =($G10/Assumptions!$E$8+($H10/Assumptions!$E$14-$G10/Assumptions!$E$8)*(T$4-2019)/6)*INDEX(Assumptions!$E$5:$E$14,MATCH(T$4,Assumptions!$A$5:$A$14,0)) -> 5150967
A11: Arlington County | B11: County | C11: 43737164 | D11: 55138617 | E11: 25689698 | F11: 34138301 | G11: =C11+E11 -> 69426862 | H11: =D11+F11 -> 89276918 | I11: =IFERROR((D11/C11)^(1/6)-1,0) -> 0.039363692 | J11: =IFERROR((H11/G11)^(1/6)-1,0) -> 0.042802208 | K11: =($G11/Assumptions!$E$8+($H11/Assumptions!$E$14-$G11/Assumptions!$E$8)*(K$4-2019)/6)*INDEX(Assumptions!$E$5:$E$14,MATCH(K$4,Assumptions!$A$5:$A$14,0)) -> 64944608 | L11: =($G11/Assumptions!$E$8+($H11/Assumptions!$E$14-$G11/Assumptions!$E$8)*(L$4-2019)/6)*INDEX(Assumptions!$E$5:$E$14,MATCH(L$4,Assumptions!$A$5:$A$14,0)) -> 65945538 | M11: =($G11/Assumptions!$E$8+($H11/Assumptions!$E$14-$G11/Assumptions!$E$8)*(M$4-2019)/6)*INDEX(Assumptions!$E$5:$E$14,MATCH(M$4,Assumptions!$A$5:$A$14,0)) -> 67164453 | N11: =($G11/Assumptions!$E$8+($H11/Assumptions!$E$14-$G11/Assumptions!$E$8)*(N$4-2019)/6)*INDEX(Assumptions!$E$5:$E$14,MATCH(N$4,Assumptions!$A$5:$A$14,0)) -> 69426862 | O11: =($G11/Assumptions!$E$8+($H11/Assumptions!$E$14-$G11/Assumptions!$E$8)*(O$4-2019)/6)*INDEX(Assumptions!$E$5:$E$14,MATCH(O$4,Assumptions!$A$5:$A$14,0)) -> 72558801 | P11: =($G11/Assumptions!$E$8+($H11/Assumptions!$E$14-$G11/Assumptions!$E$8)*(P$4-2019)/6)*INDEX(Assumptions!$E$5:$E$14,MATCH(P$4,Assumptions!$A$5:$A$14,0)) -> 78411360 | Q11: =($G11/Assumptions!$E$8+($H11/Assumptions!$E$14-$G11/Assumptions!$E$8)*(Q$4-2019)/6)*INDEX(Assumptions!$E$5:$E$14,MATCH(Q$4,Assumptions!$A$5:$A$14,0)) -> 87751546 | R11: =($G11/Assumptions!$E$8+($H11/Assumptions!$E$14-$G11/Assumptions!$E$8)*(R$4-2019)/6)*INDEX(Assumptions!$E$5:$E$14,MATCH(R$4,Assumptions!$A$5:$A$14,0)) -> 90345509 | ... T11: =($G11/Assumptions!$E$8+($H11/Assumptions!$E$14-$G11/Assumptions!$E$8)*(T$4-2019)/6)*INDEX(Assumptions!$E$5:$E$14,MATCH(T$4,Assumptions!$A$5:$A$14,0)) -> 89276918
A12: Augusta County | B12: County | C12: 6229458 | D12: 9993991 | E12: 10569425 | F12: 12920072 | G12: =C12+E12 -> 16798883 | H12: =D12+F12 -> 22914063 | I12: =IFERROR((D12/C12)^(1/6)-1,0) -> 0.081968911 | J12: =IFERROR((H12/G12)^(1/6)-1,0) -> 0.053101625 | K12: =($G12/Assumptions!$E$8+($H12/Assumptions!$E$14-$G12/Assumptions!$E$8)*(K$4-2019)/6)*INDEX(Assumptions!$E$5:$E$14,MATCH(K$4,Assumptions!$A$5:$A$14,0)) -> 15261500 | L12: =($G12/Assumptions!$E$8+($H12/Assumptions!$E$14-$G12/Assumptions!$E$8)*(L$4-2019)/6)*INDEX(Assumptions!$E$5:$E$14,MATCH(L$4,Assumptions!$A$5:$A$14,0)) -> 15648228 | M12: =($G12/Assumptions!$E$8+($H12/Assumptions!$E$14-$G12/Assumptions!$E$8)*(M$4-2019)/6)*INDEX(Assumptions!$E$5:$E$14,MATCH(M$4,Assumptions!$A$5:$A$14,0)) -> 16093559 | N12: =($G12/Assumptions!$E$8+($H12/Assumptions!$E$14-$G12/Assumptions!$E$8)*(N$4-2019)/6)*INDEX(Assumptions!$E$5:$E$14,MATCH(N$4,Assumptions!$A$5:$A$14,0)) -> 16798883 | O12: =($G12/Assumptions!$E$8+($H12/Assumptions!$E$14-$G12/Assumptions!$E$8)*(O$4-2019)/6)*INDEX(Assumptions!$E$5:$E$14,MATCH(O$4,Assumptions!$A$5:$A$14,0)) -> 17729271 | P12: =($G12/Assumptions!$E$8+($H12/Assumptions!$E$14-$G12/Assumptions!$E$8)*(P$4-2019)/6)*INDEX(Assumptions!$E$5:$E$14,MATCH(P$4,Assumptions!$A$5:$A$14,0)) -> 19347976 | Q12: =($G12/Assumptions!$E$8+($H12/Assumptions!$E$14-$G12/Assumptions!$E$8)*(Q$4-2019)/6)*INDEX(Assumptions!$E$5:$E$14,MATCH(Q$4,Assumptions!$A$5:$A$14,0)) -> 21866295 | R12: =($G12/Assumptions!$E$8+($H12/Assumptions!$E$14-$G12/Assumptions!$E$8)*(R$4-2019)/6)*INDEX(Assumptions!$E$5:$E$14,MATCH(R$4,Assumptions!$A$5:$A$14,0)) -> 22735222 | ... T12: =($G12/Assumptions!$E$8+($H12/Assumptions!$E$14-$G12/Assumptions!$E$8)*(T$4-2019)/6)*INDEX(Assumptions!$E$5:$E$14,MATCH(T$4,Assumptions!$A$5:$A$14,0)) -> 22914063
A13: Bath County | B13: County | C13: 822596 | D13: 1312575 | E13: 528675 | F13: 572584 | G13: =C13+E13 -> 1351271 | H13: =D13+F13 -> 1885159 | I13: =IFERROR((D13/C13)^(1/6)-1,0) -> 0.080993102 | J13: =IFERROR((H13/G13)^(1/6)-1,0) -> 0.057063122 | K13: =($G13/Assumptions!$E$8+($H13/Assumptions!$E$14-$G13/Assumptions!$E$8)*(K$4-2019)/6)*INDEX(Assumptions!$E$5:$E$14,MATCH(K$4,Assumptions!$A$5:$A$14,0)) -> 1213114.2 | L13: =($G13/Assumptions!$E$8+($H13/Assumptions!$E$14-$G13/Assumptions!$E$8)*(L$4-2019)/6)*INDEX(Assumptions!$E$5:$E$14,MATCH(L$4,Assumptions!$A$5:$A$14,0)) -> 1248847.8 | M13: =($G13/Assumptions!$E$8+($H13/Assumptions!$E$14-$G13/Assumptions!$E$8)*(M$4-2019)/6)*INDEX(Assumptions!$E$5:$E$14,MATCH(M$4,Assumptions!$A$5:$A$14,0)) -> 1289482.6 | N13: =($G13/Assumptions!$E$8+($H13/Assumptions!$E$14-$G13/Assumptions!$E$8)*(N$4-2019)/6)*INDEX(Assumptions!$E$5:$E$14,MATCH(N$4,Assumptions!$A$5:$A$14,0)) -> 1351271 | O13: =($G13/Assumptions!$E$8+($H13/Assumptions!$E$14-$G13/Assumptions!$E$8)*(O$4-2019)/6)*INDEX(Assumptions!$E$5:$E$14,MATCH(O$4,Assumptions!$A$5:$A$14,0)) -> 1431632.5 | P13: =($G13/Assumptions!$E$8+($H13/Assumptions!$E$14-$G13/Assumptions!$E$8)*(P$4-2019)/6)*INDEX(Assumptions!$E$5:$E$14,MATCH(P$4,Assumptions!$A$5:$A$14,0)) -> 1568321.9 | Q13: =($G13/Assumptions!$E$8+($H13/Assumptions!$E$14-$G13/Assumptions!$E$8)*(Q$4-2019)/6)*INDEX(Assumptions!$E$5:$E$14,MATCH(Q$4,Assumptions!$A$5:$A$14,0)) -> 1779158 | R13: =($G13/Assumptions!$E$8+($H13/Assumptions!$E$14-$G13/Assumptions!$E$8)*(R$4-2019)/6)*INDEX(Assumptions!$E$5:$E$14,MATCH(R$4,Assumptions!$A$5:$A$14,0)) -> 1856774.7 | ... T13: =($G13/Assumptions!$E$8+($H13/Assumptions!$E$14-$G13/Assumptions!$E$8)*(T$4-2019)/6)*INDEX(Assumptions!$E$5:$E$14,MATCH(T$4,Assumptions!$A$5:$A$14,0)) -> 1885159
A14: Bedford County | B14: County | C14: 6395201 | D14: 10883951 | E14: 11604747 | F14: 13413051 | G14: =C14+E14 -> 17999948 | H14: =D14+F14 -> 24297002 | I14: =IFERROR((D14/C14)^(1/6)-1,0) -> 0.092669272 | J14: =IFERROR((H14/G14)^(1/6)-1,0) -> 0.05126831 | K14: =($G14/Assumptions!$E$8+($H14/Assumptions!$E$14-$G14/Assumptions!$E$8)*(K$4-2019)/6)*INDEX(Assumptions!$E$5:$E$14,MATCH(K$4,Assumptions!$A$5:$A$14,0)) -> 16440767 | L14: =($G14/Assumptions!$E$8+($H14/Assumptions!$E$14-$G14/Assumptions!$E$8)*(L$4-2019)/6)*INDEX(Assumptions!$E$5:$E$14,MATCH(L$4,Assumptions!$A$5:$A$14,0)) -> 16827019 | M14: =($G14/Assumptions!$E$8+($H14/Assumptions!$E$14-$G14/Assumptions!$E$8)*(M$4-2019)/6)*INDEX(Assumptions!$E$5:$E$14,MATCH(M$4,Assumptions!$A$5:$A$14,0)) -> 17274922 | N14: =($G14/Assumptions!$E$8+($H14/Assumptions!$E$14-$G14/Assumptions!$E$8)*(N$4-2019)/6)*INDEX(Assumptions!$E$5:$E$14,MATCH(N$4,Assumptions!$A$5:$A$14,0)) -> 17999948 | O14: =($G14/Assumptions!$E$8+($H14/Assumptions!$E$14-$G14/Assumptions!$E$8)*(O$4-2019)/6)*INDEX(Assumptions!$E$5:$E$14,MATCH(O$4,Assumptions!$A$5:$A$14,0)) -> 18963275 | P14: =($G14/Assumptions!$E$8+($H14/Assumptions!$E$14-$G14/Assumptions!$E$8)*(P$4-2019)/6)*INDEX(Assumptions!$E$5:$E$14,MATCH(P$4,Assumptions!$A$5:$A$14,0)) -> 20658289 | Q14: =($G14/Assumptions!$E$8+($H14/Assumptions!$E$14-$G14/Assumptions!$E$8)*(Q$4-2019)/6)*INDEX(Assumptions!$E$5:$E$14,MATCH(Q$4,Assumptions!$A$5:$A$14,0)) -> 23306391 | R14: =($G14/Assumptions!$E$8+($H14/Assumptions!$E$14-$G14/Assumptions!$E$8)*(R$4-2019)/6)*INDEX(Assumptions!$E$5:$E$14,MATCH(R$4,Assumptions!$A$5:$A$14,0)) -> 24190491 | ... T14: =($G14/Assumptions!$E$8+($H14/Assumptions!$E$14-$G14/Assumptions!$E$8)*(T$4-2019)/6)*INDEX(Assumptions!$E$5:$E$14,MATCH(T$4,Assumptions!$A$5:$A$14,0)) -> 24297002
A15: Bland County | B15: County | C15: 378149 | D15: 607811 | E15: 784038 | F15: 797014 | G15: =C15+E15 -> 1162187 | H15: =D15+F15 -> 1404825 | I15: =IFERROR((D15/C15)^(1/6)-1,0) -> 0.082308161 | J15: =IFERROR((H15/G15)^(1/6)-1,0) -> 0.032106157 | K15: =($G15/Assumptions!$E$8+($H15/Assumptions!$E$14-$G15/Assumptions!$E$8)*(K$4-2019)/6)*INDEX(Assumptions!$E$5:$E$14,MATCH(K$4,Assumptions!$A$5:$A$14,0)) -> 1118092.9 | L15: =($G15/Assumptions!$E$8+($H15/Assumptions!$E$14-$G15/Assumptions!$E$8)*(L$4-2019)/6)*INDEX(Assumptions!$E$5:$E$14,MATCH(L$4,Assumptions!$A$5:$A$14,0)) -> 1124973.3 | M15: =($G15/Assumptions!$E$8+($H15/Assumptions!$E$14-$G15/Assumptions!$E$8)*(M$4-2019)/6)*INDEX(Assumptions!$E$5:$E$14,MATCH(M$4,Assumptions!$A$5:$A$14,0)) -> 1135102.6 | N15: =($G15/Assumptions!$E$8+($H15/Assumptions!$E$14-$G15/Assumptions!$E$8)*(N$4-2019)/6)*INDEX(Assumptions!$E$5:$E$14,MATCH(N$4,Assumptions!$A$5:$A$14,0)) -> 1162187 | O15: =($G15/Assumptions!$E$8+($H15/Assumptions!$E$14-$G15/Assumptions!$E$8)*(O$4-2019)/6)*INDEX(Assumptions!$E$5:$E$14,MATCH(O$4,Assumptions!$A$5:$A$14,0)) -> 1202825 | P15: =($G15/Assumptions!$E$8+($H15/Assumptions!$E$14-$G15/Assumptions!$E$8)*(P$4-2019)/6)*INDEX(Assumptions!$E$5:$E$14,MATCH(P$4,Assumptions!$A$5:$A$14,0)) -> 1286954.3 | Q15: =($G15/Assumptions!$E$8+($H15/Assumptions!$E$14-$G15/Assumptions!$E$8)*(Q$4-2019)/6)*INDEX(Assumptions!$E$5:$E$14,MATCH(Q$4,Assumptions!$A$5:$A$14,0)) -> 1425658.2 | R15: =($G15/Assumptions!$E$8+($H15/Assumptions!$E$14-$G15/Assumptions!$E$8)*(R$4-2019)/6)*INDEX(Assumptions!$E$5:$E$14,MATCH(R$4,Assumptions!$A$5:$A$14,0)) -> 1452596.3 | ... T15: =($G15/Assumptions!$E$8+($H15/Assumptions!$E$14-$G15/Assumptions!$E$8)*(T$4-2019)/6)*INDEX(Assumptions!$E$5:$E$14,MATCH(T$4,Assumptions!$A$5:$A$14,0)) -> 1404825
A16: Botetourt County | B16: County | C16: 3006691 | D16: 4739530 | E16: 5018335 | F16: 5714334 | G16: =C16+E16 -> 8025026 | H16: =D16+F16 -> 10453864 | I16: =IFERROR((D16/C16)^(1/6)-1,0) -> 0.078800353 | J16: =IFERROR((H16/G16)^(1/6)-1,0) -> 0.0450532 | K16: =($G16/Assumptions!$E$8+($H16/Assumptions!$E$14-$G16/Assumptions!$E$8)*(K$4-2019)/6)*INDEX(Assumptions!$E$5:$E$14,MATCH(K$4,Assumptions!$A$5:$A$14,0)) -> 7460549.4 | L16: =($G16/Assumptions!$E$8+($H16/Assumptions!$E$14-$G16/Assumptions!$E$8)*(L$4-2019)/6)*INDEX(Assumptions!$E$5:$E$14,MATCH(L$4,Assumptions!$A$5:$A$14,0)) -> 7591048.7 | M16: =($G16/Assumptions!$E$8+($H16/Assumptions!$E$14-$G16/Assumptions!$E$8)*(M$4-2019)/6)*INDEX(Assumptions!$E$5:$E$14,MATCH(M$4,Assumptions!$A$5:$A$14,0)) -> 7747344.5 | N16: =($G16/Assumptions!$E$8+($H16/Assumptions!$E$14-$G16/Assumptions!$E$8)*(N$4-2019)/6)*INDEX(Assumptions!$E$5:$E$14,MATCH(N$4,Assumptions!$A$5:$A$14,0)) -> 8025026 | O16: =($G16/Assumptions!$E$8+($H16/Assumptions!$E$14-$G16/Assumptions!$E$8)*(O$4-2019)/6)*INDEX(Assumptions!$E$5:$E$14,MATCH(O$4,Assumptions!$A$5:$A$14,0)) -> 8404718.3 | P16: =($G16/Assumptions!$E$8+($H16/Assumptions!$E$14-$G16/Assumptions!$E$8)*(P$4-2019)/6)*INDEX(Assumptions!$E$5:$E$14,MATCH(P$4,Assumptions!$A$5:$A$14,0)) -> 9101960.5 | Q16: =($G16/Assumptions!$E$8+($H16/Assumptions!$E$14-$G16/Assumptions!$E$8)*(Q$4-2019)/6)*INDEX(Assumptions!$E$5:$E$14,MATCH(Q$4,Assumptions!$A$5:$A$14,0)) -> 10208044 | R16: =($G16/Assumptions!$E$8+($H16/Assumptions!$E$14-$G16/Assumptions!$E$8)*(R$4-2019)/6)*INDEX(Assumptions!$E$5:$E$14,MATCH(R$4,Assumptions!$A$5:$A$14,0)) -> 10532588 | ... T16: =($G16/Assumptions!$E$8+($H16/Assumptions!$E$14-$G16/Assumptions!$E$8)*(T$4-2019)/6)*INDEX(Assumptions!$E$5:$E$14,MATCH(T$4,Assumptions!$A$5:$A$14,0)) -> 10453864
... A137: Winchester City | B137: City | C137: 9951036 | D137: 13385081 | E137: 4037675 | F137: 4875119 | G137: =C137+E137 -> 13988711 | H137: =D137+F137 -> 18260200 | I137: =IFERROR((D137/C137)^(1/6)-1,0) -> 0.050651741 | J137: =IFERROR((H137/G137)^(1/6)-1,0) -> 0.045413182 | K137: =($G137/Assumptions!$E$8+($H137/Assumptions!$E$14-$G137/Assumptions!$E$8)*(K$4-2019)/6)*INDEX(Assumptions!$E$5:$E$14,MATCH(K$4,Assumptions!$A$5:$A$14,0)) -> 12991743 | L137: =($G137/Assumptions!$E$8+($H137/Assumptions!$E$14-$G137/Assumptions!$E$8)*(L$4-2019)/6)*INDEX(Assumptions!$E$5:$E$14,MATCH(L$4,Assumptions!$A$5:$A$14,0)) -> 13223373 | M137: =($G137/Assumptions!$E$8+($H137/Assumptions!$E$14-$G137/Assumptions!$E$8)*(M$4-2019)/6)*INDEX(Assumptions!$E$5:$E$14,MATCH(M$4,Assumptions!$A$5:$A$14,0)) -> 13500138 | N137: =($G137/Assumptions!$E$8+($H137/Assumptions!$E$14-$G137/Assumptions!$E$8)*(N$4-2019)/6)*INDEX(Assumptions!$E$5:$E$14,MATCH(N$4,Assumptions!$A$5:$A$14,0)) -> 13988711 | O137: =($G137/Assumptions!$E$8+($H137/Assumptions!$E$14-$G137/Assumptions!$E$8)*(O$4-2019)/6)*INDEX(Assumptions!$E$5:$E$14,MATCH(O$4,Assumptions!$A$5:$A$14,0)) -> 14655524 | P137: =($G137/Assumptions!$E$8+($H137/Assumptions!$E$14-$G137/Assumptions!$E$8)*(P$4-2019)/6)*INDEX(Assumptions!$E$5:$E$14,MATCH(P$4,Assumptions!$A$5:$A$14,0)) -> 15876731 | Q137: =($G137/Assumptions!$E$8+($H137/Assumptions!$E$14-$G137/Assumptions!$E$8)*(Q$4-2019)/6)*INDEX(Assumptions!$E$5:$E$14,MATCH(Q$4,Assumptions!$A$5:$A$14,0)) -> 17812205 | R137: =($G137/Assumptions!$E$8+($H137/Assumptions!$E$14-$G137/Assumptions!$E$8)*(R$4-2019)/6)*INDEX(Assumptions!$E$5:$E$14,MATCH(R$4,Assumptions!$A$5:$A$14,0)) -> 18384861 | ... T137: =($G137/Assumptions!$E$8+($H137/Assumptions!$E$14-$G137/Assumptions!$E$8)*(T$4-2019)/6)*INDEX(Assumptions!$E$5:$E$14,MATCH(T$4,Assumptions!$A$5:$A$14,0)) -> 18260200
A138: TOTAL — all localities | C138: =SUM(C5:C137) -> 1292803735 | D138: =SUM(D5:D137) -> 1876912593 | E138: =SUM(E5:E137) -> 1290310946 | F138: =SUM(F5:F137) -> 1564222649 | G138: =SUM(G5:G137) -> 2583114681 | H138: =SUM(H5:H137) -> 3441135242 | K138: =SUM(K5:K137) -> 2.3751155e+09 | L138: =SUM(L5:L137) -> 2.4255168e+09 | M138: =SUM(M5:M137) -> 2.4845618e+09 | N138: =SUM(N5:N137) -> 2583114681 | O138: =SUM(O5:O137) -> 2.715355e+09 | P138: =SUM(P5:P137) -> 2.951553e+09 | Q138: =SUM(Q5:Q137) -> 3.3225869e+09 | R138: =SUM(R5:R137) -> 3.4410673e+09 | ... T138: =SUM(T5:T137) -> 3441135242

Sheet Projection FY26-FY45
A1: Projected Retail Sales Tax Distribution by Locality — FY2026 to FY2045
A2: Total of both streams (state 1% education share + 1% local option), nominal dollars. Growth rate per locality is built from the Assumptions tab — change the levers there, not here.
A4: Locality | B4: Type | C4: FY2025 Total ($) — actual | D4: Applied annual growth rate | E4: 2026 | F4: 2027 | G4: 2028 | H4: 2029 | I4: 2030 | J4: 2031 | K4: 2032 | L4: 2033 | M4: 2034 | N4: 2035 | O4: 2036 | P4: 2037 | Q4: 2038 | R4: 2039 | S4: 2040 | T4: 2041 | U4: 2042 | V4: 2043 | W4: 2044 | X4: 2045
A5: ='Historical FY16-FY25'!A5 -> Accomack County | B5: ='Historical FY16-FY25'!B5 -> County | C5: ='Historical FY16-FY25'!H5 -> 11822596 | D5: =MIN(Assumptions!$B$27,MAX(Assumptions!$B$26,Assumptions!$B$24+Assumptions!$B$25*('Historical FY16-FY25'!J5-Assumptions!$B$20))) -> 0.039494374 | E5: =$C5*(1+$D5)^(E$4-2025) -> 12289522 | F5: =$C5*(1+$D5)^(F$4-2025) -> 12774889 | G5: =$C5*(1+$D5)^(G$4-2025) -> 13279425 | H5: =$C5*(1+$D5)^(H$4-2025) -> 13803888 | I5: =$C5*(1+$D5)^(I$4-2025) -> 14349064 | J5: =$C5*(1+$D5)^(J$4-2025) -> 14915771 | K5: =$C5*(1+$D5)^(K$4-2025) -> 15504860 | L5: =$C5*(1+$D5)^(L$4-2025) -> 16117215 | ... X5: =$C5*(1+$D5)^(X$4-2025) -> 25654037
A6: ='Historical FY16-FY25'!A6 -> Albemarle County | B6: ='Historical FY16-FY25'!B6 -> County | C6: ='Historical FY16-FY25'!H6 -> 45437928 | D6: =MIN(Assumptions!$B$27,MAX(Assumptions!$B$26,Assumptions!$B$24+Assumptions!$B$25*('Historical FY16-FY25'!J6-Assumptions!$B$20))) -> 0.049296427 | E6: =$C6*(1+$D6)^(E$4-2025) -> 47677855 | F6: =$C6*(1+$D6)^(F$4-2025) -> 50028203 | G6: =$C6*(1+$D6)^(G$4-2025) -> 52494415 | H6: =$C6*(1+$D6)^(H$4-2025) -> 55082202 | I6: =$C6*(1+$D6)^(I$4-2025) -> 57797558 | J6: =$C6*(1+$D6)^(J$4-2025) -> 60646771 | K6: =$C6*(1+$D6)^(K$4-2025) -> 63636440 | L6: =$C6*(1+$D6)^(L$4-2025) -> 66773489 | ... X6: =$C6*(1+$D6)^(X$4-2025) -> 1.1895492e+08
A7: ='Historical FY16-FY25'!A7 -> Alleghany County | B7: ='Historical FY16-FY25'!B7 -> County | C7: ='Historical FY16-FY25'!H7 -> 3604117 | D7: =MIN(Assumptions!$B$27,MAX(Assumptions!$B$26,Assumptions!$B$24+Assumptions!$B$25*('Historical FY16-FY25'!J7-Assumptions!$B$20))) -> 0.030452822 | E7: =$C7*(1+$D7)^(E$4-2025) -> 3713872.5 | F7: =$C7*(1+$D7)^(F$4-2025) -> 3826970.4 | G7: =$C7*(1+$D7)^(G$4-2025) -> 3943512.5 | H7: =$C7*(1+$D7)^(H$4-2025) -> 4063603.6 | I7: =$C7*(1+$D7)^(I$4-2025) -> 4187351.8 | J7: =$C7*(1+$D7)^(J$4-2025) -> 4314868.4 | K7: =$C7*(1+$D7)^(K$4-2025) -> 4446268.4 | L7: =$C7*(1+$D7)^(L$4-2025) -> 4581669.8 | ... X7: =$C7*(1+$D7)^(X$4-2025) -> 6566911.1
A8: ='Historical FY16-FY25'!A8 -> Amelia County | B8: ='Historical FY16-FY25'!B8 -> County | C8: ='Historical FY16-FY25'!H8 -> 3693984 | D8: =MIN(Assumptions!$B$27,MAX(Assumptions!$B$26,Assumptions!$B$24+Assumptions!$B$25*('Historical FY16-FY25'!J8-Assumptions!$B$20))) -> 0.046320239 | E8: =$C8*(1+$D8)^(E$4-2025) -> 3865090.2 | F8: =$C8*(1+$D8)^(F$4-2025) -> 4044122.1 | G8: =$C8*(1+$D8)^(G$4-2025) -> 4231446.8 | H8: =$C8*(1+$D8)^(H$4-2025) -> 4427448.5 | I8: =$C8*(1+$D8)^(I$4-2025) -> 4632528.9 | J8: =$C8*(1+$D8)^(J$4-2025) -> 4847108.8 | K8: =$C8*(1+$D8)^(K$4-2025) -> 5071628 | L8: =$C8*(1+$D8)^(L$4-2025) -> 5306547 | ... X8: =$C8*(1+$D8)^(X$4-2025) -> 9136661.4
A9: ='Historical FY16-FY25'!A9 -> Amherst County | B9: ='Historical FY16-FY25'!B9 -> County | C9: ='Historical FY16-FY25'!H9 -> 9873279 | D9: =MIN(Assumptions!$B$27,MAX(Assumptions!$B$26,Assumptions!$B$24+Assumptions!$B$25*('Historical FY16-FY25'!J9-Assumptions!$B$20))) -> 0.04445156 | E9: =$C9*(1+$D9)^(E$4-2025) -> 10312162 | F9: =$C9*(1+$D9)^(F$4-2025) -> 10770553 | G9: =$C9*(1+$D9)^(G$4-2025) -> 11249321 | H9: =$C9*(1+$D9)^(H$4-2025) -> 11749371 | I9: =$C9*(1+$D9)^(I$4-2025) -> 12271649 | J9: =$C9*(1+$D9)^(J$4-2025) -> 12817143 | K9: =$C9*(1+$D9)^(K$4-2025) -> 13386885 | L9: =$C9*(1+$D9)^(L$4-2025) -> 13981953 | ... X9: =$C9*(1+$D9)^(X$4-2025) -> 23562831
A10: ='Historical FY16-FY25'!A10 -> Appomattox County | B10: ='Historical FY16-FY25'!B10 -> County | C10: ='Historical FY16-FY25'!H10 -> 5150967 | D10: =MIN(Assumptions!$B$27,MAX(Assumptions!$B$26,Assumptions!$B$24+Assumptions!$B$25*('Historical FY16-FY25'!J10-Assumptions!$B$20))) -> 0.047968776 | E10: =$C10*(1+$D10)^(E$4-2025) -> 5398052.6 | F10: =$C10*(1+$D10)^(F$4-2025) -> 5656990.6 | G10: =$C10*(1+$D10)^(G$4-2025) -> 5928349.5 | H10: =$C10*(1+$D10)^(H$4-2025) -> 6212725.1 | I10: =$C10*(1+$D10)^(I$4-2025) -> 6510741.9 | J10: =$C10*(1+$D10)^(J$4-2025) -> 6823054.3 | K10: =$C10*(1+$D10)^(K$4-2025) -> 7150347.8 | L10: =$C10*(1+$D10)^(L$4-2025) -> 7493341.3 | ... X10: =$C10*(1+$D10)^(X$4-2025) -> 13147877
A11: ='Historical FY16-FY25'!A11 -> Arlington County | B11: ='Historical FY16-FY25'!B11 -> County | C11: ='Historical FY16-FY25'!H11 -> 89276918 | D11: =MIN(Assumptions!$B$27,MAX(Assumptions!$B$26,Assumptions!$B$24+Assumptions!$B$25*('Historical FY16-FY25'!J11-Assumptions!$B$20))) -> 0.041409246 | E11: =$C11*(1+$D11)^(E$4-2025) -> 92973808 | F11: =$C11*(1+$D11)^(F$4-2025) -> 96823783 | G11: =$C11*(1+$D11)^(G$4-2025) -> 1.0083318e+08 | H11: =$C11*(1+$D11)^(H$4-2025) -> 1.0500861e+08 | I11: =$C11*(1+$D11)^(I$4-2025) -> 1.0935694e+08 | J11: =$C11*(1+$D11)^(J$4-2025) -> 1.1388532e+08 | K11: =$C11*(1+$D11)^(K$4-2025) -> 1.1860123e+08 | L11: =$C11*(1+$D11)^(L$4-2025) -> 1.2351242e+08 | ... X11: =$C11*(1+$D11)^(X$4-2025) -> 2.0098691e+08
A12: ='Historical FY16-FY25'!A12 -> Augusta County | B12: ='Historical FY16-FY25'!B12 -> County | C12: ='Historical FY16-FY25'!H12 -> 22914063 | D12: =MIN(Assumptions!$B$27,MAX(Assumptions!$B$26,Assumptions!$B$24+Assumptions!$B$25*('Historical FY16-FY25'!J12-Assumptions!$B$20))) -> 0.046558955 | E12: =$C12*(1+$D12)^(E$4-2025) -> 23980918 | F12: =$C12*(1+$D12)^(F$4-2025) -> 25097444 | G12: =$C12*(1+$D12)^(G$4-2025) -> 26265955 | H12: =$C12*(1+$D12)^(H$4-2025) -> 27488870 | I12: =$C12*(1+$D12)^(I$4-2025) -> 28768724 | J12: =$C12*(1+$D12)^(J$4-2025) -> 30108165 | K12: =$C12*(1+$D12)^(K$4-2025) -> 31509970 | L12: =$C12*(1+$D12)^(L$4-2025) -> 32977041 | ... X12: =$C12*(1+$D12)^(X$4-2025) -> 56934572
A13: ='Historical FY16-FY25'!A13 -> Bath County | B13: ='Historical FY16-FY25'!B13 -> County | C13: ='Historical FY16-FY25'!H13 -> 1885159 | D13: =MIN(Assumptions!$B$27,MAX(Assumptions!$B$26,Assumptions!$B$24+Assumptions!$B$25*('Historical FY16-FY25'!J13-Assumptions!$B$20))) -> 0.048539703 | E13: =$C13*(1+$D13)^(E$4-2025) -> 1976664.1 | F13: =$C13*(1+$D13)^(F$4-2025) -> 2072610.7 | G13: =$C13*(1+$D13)^(G$4-2025) -> 2173214.7 | H13: =$C13*(1+$D13)^(H$4-2025) -> 2278701.8 | I13: =$C13*(1+$D13)^(I$4-2025) -> 2389309.4 | J13: =$C13*(1+$D13)^(J$4-2025) -> 2505285.7 | K13: =$C13*(1+$D13)^(K$4-2025) -> 2626891.6 | L13: =$C13*(1+$D13)^(L$4-2025) -> 2754400.1 | ... X13: =$C13*(1+$D13)^(X$4-2025) -> 4864582.6
A14: ='Historical FY16-FY25'!A14 -> Bedford County | B14: ='Historical FY16-FY25'!B14 -> County | C14: ='Historical FY16-FY25'!H14 -> 24297002 | D14: =MIN(Assumptions!$B$27,MAX(Assumptions!$B$26,Assumptions!$B$24+Assumptions!$B$25*('Historical FY16-FY25'!J14-Assumptions!$B$20))) -> 0.045642297 | E14: =$C14*(1+$D14)^(E$4-2025) -> 25405973 | F14: =$C14*(1+$D14)^(F$4-2025) -> 26565560 | G14: =$C14*(1+$D14)^(G$4-2025) -> 27778073 | H14: =$C14*(1+$D14)^(H$4-2025) -> 29045928 | I14: =$C14*(1+$D14)^(I$4-2025) -> 30371651 | J14: =$C14*(1+$D14)^(J$4-2025) -> 31757883 | K14: =$C14*(1+$D14)^(K$4-2025) -> 33207386 | L14: =$C14*(1+$D14)^(L$4-2025) -> 34723047 | ... X14: =$C14*(1+$D14)^(X$4-2025) -> 59321967
A15: ='Historical FY16-FY25'!A15 -> Bland County | B15: ='Historical FY16-FY25'!B15 -> County | C15: ='Historical FY16-FY25'!H15 -> 1404825 | D15: =MIN(Assumptions!$B$27,MAX(Assumptions!$B$26,Assumptions!$B$24+Assumptions!$B$25*('Historical FY16-FY25'!J15-Assumptions!$B$20))) -> 0.036061221 | E15: =$C15*(1+$D15)^(E$4-2025) -> 1455484.7 | F15: =$C15*(1+$D15)^(F$4-2025) -> 1507971.3 | G15: =$C15*(1+$D15)^(G$4-2025) -> 1562350.5 | H15: =$C15*(1+$D15)^(H$4-2025) -> 1618690.8 | I15: =$C15*(1+$D15)^(I$4-2025) -> 1677062.8 | J15: =$C15*(1+$D15)^(J$4-2025) -> 1737539.7 | K15: =$C15*(1+$D15)^(K$4-2025) -> 1800197.5 | L15: =$C15*(1+$D15)^(L$4-2025) -> 1865114.8 | ... X15: =$C15*(1+$D15)^(X$4-2025) -> 2853189.4
A16: ='Historical FY16-FY25'!A16 -> Botetourt County | B16: ='Historical FY16-FY25'!B16 -> County | C16: ='Historical FY16-FY25'!H16 -> 10453864 | D16: =MIN(Assumptions!$B$27,MAX(Assumptions!$B$26,Assumptions!$B$24+Assumptions!$B$25*('Historical FY16-FY25'!J16-Assumptions!$B$20))) -> 0.042534743 | E16: =$C16*(1+$D16)^(E$4-2025) -> 10898516 | F16: =$C16*(1+$D16)^(F$4-2025) -> 11362082 | G16: =$C16*(1+$D16)^(G$4-2025) -> 11845365 | H16: =$C16*(1+$D16)^(H$4-2025) -> 12349205 | I16: =$C16*(1+$D16)^(I$4-2025) -> 12874475 | J16: =$C16*(1+$D16)^(J$4-2025) -> 13422088 | K16: =$C16*(1+$D16)^(K$4-2025) -> 13992993 | L16: =$C16*(1+$D16)^(L$4-2025) -> 14588181 | ... X16: =$C16*(1+$D16)^(X$4-2025) -> 24048477
... A137: ='Historical FY16-FY25'!A137 -> Winchester City | B137: ='Historical FY16-FY25'!B137 -> City | C137: ='Historical FY16-FY25'!H137 -> 18260200 | D137: =MIN(Assumptions!$B$27,MAX(Assumptions!$B$26,Assumptions!$B$24+Assumptions!$B$25*('Historical FY16-FY25'!J137-Assumptions!$B$20))) -> 0.042714733 | E137: =$C137*(1+$D137)^(E$4-2025) -> 19040180 | F137: =$C137*(1+$D137)^(F$4-2025) -> 19853476 | G137: =$C137*(1+$D137)^(G$4-2025) -> 20701512 | H137: =$C137*(1+$D137)^(H$4-2025) -> 21585771 | I137: =$C137*(1+$D137)^(I$4-2025) -> 22507802 | J137: =$C137*(1+$D137)^(J$4-2025) -> 23469216 | K137: =$C137*(1+$D137)^(K$4-2025) -> 24471698 | L137: =$C137*(1+$D137)^(L$4-2025) -> 25517000 | ... X137: =$C137*(1+$D137)^(X$4-2025) -> 42151762
A138: TOTAL — all localities | C138: =SUM(C5:C137) -> 3441135242 | E138: =SUM(E5:E137) -> 3.5948234e+09 | F138: =SUM(F5:F137) -> 3.7554672e+09 | G138: =SUM(G5:G137) -> 3.9233859e+09 | H138: =SUM(H5:H137) -> 4.0989134e+09 | I138: =SUM(I5:I137) -> 4.2823992e+09 | J138: =SUM(J5:J137) -> 4.4742092e+09 | K138: =SUM(K5:K137) -> 4.674726e+09 | L138: =SUM(L5:L137) -> 4.8843506e+09 | ... X138: =SUM(X5:X137) -> 8.2845453e+09

Sheet Schools 1pct Profile
A1: Dedicated 1% Sales Tax for Schools — Locality Profile
A2: Main columns model a NEW 1% local sales tax for schools (Va. Code 58.1-605.1), estimated at the same yield as the existing 1% Local Option because it shares the base and the point-of-sale distribution.
A3: Final column shows the other reading of the request: setting aside 1% OF projected sales tax revenue. Read the caveats on the Read Me tab before circulating any of these numbers.
A5: Locality | B5: Type | C5: FY2025 Local Option 1% collected ($) — actual | D5: Applied annual growth rate | E5: Est. FY2027 yield of new 1% school levy ($) | F5: Est. FY2035 yield ($) | G5: Est. FY2045 yield ($) | H5: 20-year cumulative FY2026-FY2045 ($) | I5: Average per year over 20 yrs ($) | J5: Share of statewide school-levy pot | K5: ALT READING: 1% of FY2026 projected total distribution ($)
A6: ='Historical FY16-FY25'!A5 -> Accomack County | B6: ='Historical FY16-FY25'!B5 -> County | C6: ='Historical FY16-FY25'!D5 -> 6374893 | D6: ='Projection FY26-FY45'!D5 -> 0.039494374 | E6: =$C6*(Assumptions!$B$28/Assumptions!$B$29)*(1+$D6)^2 -> 6888381.4 | F6: =$C6*(Assumptions!$B$28/Assumptions!$B$29)*(1+$D6)^10 -> 9390621.4 | G6: =$C6*(Assumptions!$B$28/Assumptions!$B$29)*(1+$D6)^20 -> 13832980 | H6: =IF($D6=0,$C6*(Assumptions!$B$28/Assumptions!$B$29)*20,$C6*(Assumptions!$B$28/Assumptions!$B$29)*(1+$D6)*((1+$D6)^20-1)/$D6) -> 1.9629732e+08 | I6: =H6/20 -> 9814866.2 | J6: =IFERROR(H6/$H$139,0) -> 0.0031985218 | K6: ='Projection FY26-FY45'!E5*0.01 -> 122895.22
A7: ='Historical FY16-FY25'!A6 -> Albemarle County | B7: ='Historical FY16-FY25'!B6 -> County | C7: ='Historical FY16-FY25'!D6 -> 26225183 | D7: ='Projection FY26-FY45'!D6 -> 0.049296427 | E7: =$C7*(Assumptions!$B$28/Assumptions!$B$29)*(1+$D7)^2 -> 28874529 | F7: =$C7*(Assumptions!$B$28/Assumptions!$B$29)*(1+$D7)^10 -> 42432681 | G7: =$C7*(Assumptions!$B$28/Assumptions!$B$29)*(1+$D7)^20 -> 68656618 | H7: =IF($D7=0,$C7*(Assumptions!$B$28/Assumptions!$B$29)*20,$C7*(Assumptions!$B$28/Assumptions!$B$29)*(1+$D7)*((1+$D7)^20-1)/$D7) -> 9.0317202e+08 | I7: =H7/20 -> 45158601 | J7: =IFERROR(H7/$H$139,0) -> 0.01471653 | K7: ='Projection FY26-FY45'!E6*0.01 -> 476778.55
A8: ='Historical FY16-FY25'!A7 -> Alleghany County | B8: ='Historical FY16-FY25'!B7 -> County | C8: ='Historical FY16-FY25'!D7 -> 1288843 | D8: ='Projection FY26-FY45'!D7 -> 0.030452822 | E8: =$C8*(Assumptions!$B$28/Assumptions!$B$29)*(1+$D8)^2 -> 1368536.1 | F8: =$C8*(Assumptions!$B$28/Assumptions!$B$29)*(1+$D8)^10 -> 1739727.2 | G8: =$C8*(Assumptions!$B$28/Assumptions!$B$29)*(1+$D8)^20 -> 2348347 | H8: =IF($D8=0,$C8*(Assumptions!$B$28/Assumptions!$B$29)*20,$C8*(Assumptions!$B$28/Assumptions!$B$29)*(1+$D8)*((1+$D8)^20-1)/$D8) -> 35851158 | I8: =H8/20 -> 1792557.9 | J8: =IFERROR(H8/$H$139,0) -> 0.00058416848 | K8: ='Projection FY26-FY45'!E7*0.01 -> 37138.725
A9: ='Historical FY16-FY25'!A8 -> Amelia County | B9: ='Historical FY16-FY25'!B8 -> County | C9: ='Historical FY16-FY25'!D8 -> 1519698 | D9: ='Projection FY26-FY45'!D8 -> 0.046320239 | E9: =$C9*(Assumptions!$B$28/Assumptions!$B$29)*(1+$D9)^2 -> 1663744.2 | F9: =$C9*(Assumptions!$B$28/Assumptions!$B$29)*(1+$D9)^10 -> 2390031.1 | G9: =$C9*(Assumptions!$B$28/Assumptions!$B$29)*(1+$D9)^20 -> 3758805.1 | H9: =IF($D9=0,$C9*(Assumptions!$B$28/Assumptions!$B$29)*20,$C9*(Assumptions!$B$28/Assumptions!$B$29)*(1+$D9)*((1+$D9)^20-1)/$D9) -> 50578822 | I9: =H9/20 -> 2528941.1 | J9: =IFERROR(H9/$H$139,0) -> 0.00082414503 | K9: ='Projection FY26-FY45'!E8*0.01 -> 38650.902
A10: ='Historical FY16-FY25'!A9 -> Amherst County | B10: ='Historical FY16-FY25'!B9 -> County | C10: ='Historical FY16-FY25'!D9 -> 4726734 | D10: ='Projection FY26-FY45'!D9 -> 0.04445156 | E10: =$C10*(Assumptions!$B$28/Assumptions!$B$29)*(1+$D10)^2 -> 5156295.1 | F10: =$C10*(Assumptions!$B$28/Assumptions!$B$29)*(1+$D10)^10 -> 7302039.7 | G10: =$C10*(Assumptions!$B$28/Assumptions!$B$29)*(1+$D10)^20 -> 11280471 | H10: =IF($D10=0,$C10*(Assumptions!$B$28/Assumptions!$B$29)*20,$C10*(Assumptions!$B$28/Assumptions!$B$29)*(1+$D10)*((1+$D10)^20-1)/$D10) -> 1.5398921e+08 | I10: =H10/20 -> 7699460.4 | J10: =IFERROR(H10/$H$139,0) -> 0.0025091419 | K10: ='Projection FY26-FY45'!E9*0.01 -> 103121.62
A11: ='Historical FY16-FY25'!A10 -> Appomattox County | B11: ='Historical FY16-FY25'!B10 -> County | C11: ='Historical FY16-FY25'!D10 -> 2192135 | D11: ='Projection FY26-FY45'!D10 -> 0.047968776 | E11: =$C11*(Assumptions!$B$28/Assumptions!$B$29)*(1+$D11)^2 -> 2407487.2 | F11: =$C11*(Assumptions!$B$28/Assumptions!$B$29)*(1+$D11)^10 -> 3502278.9 | G11: =$C11*(Assumptions!$B$28/Assumptions!$B$29)*(1+$D11)^20 -> 5595438.9 | H11: =IF($D11=0,$C11*(Assumptions!$B$28/Assumptions!$B$29)*20,$C11*(Assumptions!$B$28/Assumptions!$B$29)*(1+$D11)*((1+$D11)^20-1)/$D11) -> 74351620 | I11: =H11/20 -> 3717581 | J11: =IFERROR(H11/$H$139,0) -> 0.0012115055 | K11: ='Projection FY26-FY45'!E10*0.01 -> 53980.526
A12: ='Historical FY16-FY25'!A11 -> Arlington County | B12: ='Historical FY16-FY25'!B11 -> County | C12: ='Historical FY16-FY25'!D11 -> 55138617 | D12: ='Projection FY26-FY45'!D11 -> 0.041409246 | E12: =$C12*(Assumptions!$B$28/Assumptions!$B$29)*(1+$D12)^2 -> 59799662 | F12: =$C12*(Assumptions!$B$28/Assumptions!$B$29)*(1+$D12)^10 -> 82731360 | G12: =$C12*(Assumptions!$B$28/Assumptions!$B$29)*(1+$D12)^20 -> 1.241322e+08 | H12: =IF($D12=0,$C12*(Assumptions!$B$28/Assumptions!$B$29)*20,$C12*(Assumptions!$B$28/Assumptions!$B$29)*(1+$D12)*((1+$D12)^20-1)/$D12) -> 1.7351332e+09 | I12: =H12/20 -> 86756658 | J12: =IFERROR(H12/$H$139,0) -> 0.02827273 | K12: ='Projection FY26-FY45'!E11*0.01 -> 929738.08
A13: ='Historical FY16-FY25'!A12 -> Augusta County | B13: ='Historical FY16-FY25'!B12 -> County | C13: ='Historical FY16-FY25'!D12 -> 9993991 | D13: ='Projection FY26-FY45'!D12 -> 0.046558955 | E13: =$C13*(Assumptions!$B$28/Assumptions!$B$29)*(1+$D13)^2 -> 10946275 | F13: =$C13*(Assumptions!$B$28/Assumptions!$B$29)*(1+$D13)^10 -> 15753459 | G13: =$C13*(Assumptions!$B$28/Assumptions!$B$29)*(1+$D13)^20 -> 24832070 | H13: =IF($D13=0,$C13*(Assumptions!$B$28/Assumptions!$B$29)*20,$C13*(Assumptions!$B$28/Assumptions!$B$29)*(1+$D13)*((1+$D13)^20-1)/$D13) -> 3.3353249e+08 | I13: =H13/20 -> 16676624 | J13: =IFERROR(H13/$H$139,0) -> 0.0054346687 | K13: ='Projection FY26-FY45'!E12*0.01 -> 239809.18
A14: ='Historical FY16-FY25'!A13 -> Bath County | B14: ='Historical FY16-FY25'!B13 -> County | C14: ='Historical FY16-FY25'!D13 -> 1312575 | D14: ='Projection FY26-FY45'!D13 -> 0.048539703 | E14: =$C14*(Assumptions!$B$28/Assumptions!$B$29)*(1+$D14)^2 -> 1443091.6 | F14: =$C14*(Assumptions!$B$28/Assumptions!$B$29)*(1+$D14)^10 -> 2108496.7 | G14: =$C14*(Assumptions!$B$28/Assumptions!$B$29)*(1+$D14)^20 -> 3387050.9 | H14: =IF($D14=0,$C14*(Assumptions!$B$28/Assumptions!$B$29)*20,$C14*(Assumptions!$B$28/Assumptions!$B$29)*(1+$D14)*((1+$D14)^20-1)/$D14) -> 44812189 | I14: =H14/20 -> 2240609.4 | J14: =IFERROR(H14/$H$139,0) -> 0.00073018195 | K14: ='Projection FY26-FY45'!E13*0.01 -> 19766.641
A15: ='Historical FY16-FY25'!A14 -> Bedford County | B15: ='Historical FY16-FY25'!B14 -> County | C15: ='Historical FY16-FY25'!D14 -> 10883951 | D15: ='Projection FY26-FY45'!D14 -> 0.045642297 | E15: =$C15*(Assumptions!$B$28/Assumptions!$B$29)*(1+$D15)^2 -> 11900162 | F15: =$C15*(Assumptions!$B$28/Assumptions!$B$29)*(1+$D15)^10 -> 17006620 | G15: =$C15*(Assumptions!$B$28/Assumptions!$B$29)*(1+$D15)^20 -> 26573541 | H15: =IF($D15=0,$C15*(Assumptions!$B$28/Assumptions!$B$29)*20,$C15*(Assumptions!$B$28/Assumptions!$B$29)*(1+$D15)*((1+$D15)^20-1)/$D15) -> 3.5944069e+08 | I15: =H15/20 -> 17972035 | J15: =IFERROR(H15/$H$139,0) -> 0.0058568241 | K15: ='Projection FY26-FY45'!E14*0.01 -> 254059.73
A16: ='Historical FY16-FY25'!A15 -> Bland County | B16: ='Historical FY16-FY25'!B15 -> County | C16: ='Historical FY16-FY25'!D15 -> 607811 | D16: ='Projection FY26-FY45'!D15 -> 0.036061221 | E16: =$C16*(Assumptions!$B$28/Assumptions!$B$29)*(1+$D16)^2 -> 652438.22 | F16: =$C16*(Assumptions!$B$28/Assumptions!$B$29)*(1+$D16)^10 -> 866209.1 | G16: =$C16*(Assumptions!$B$28/Assumptions!$B$29)*(1+$D16)^20 -> 1234459.7 | H16: =IF($D16=0,$C16*(Assumptions!$B$28/Assumptions!$B$29)*20,$C16*(Assumptions!$B$28/Assumptions!$B$29)*(1+$D16)*((1+$D16)^20-1)/$D16) -> 18004006 | I16: =H16/20 -> 900200.32 | J16: =IFERROR(H16/$H$139,0) -> 0.00029336216 | K16: ='Projection FY26-FY45'!E15*0.01 -> 14554.847
A17: ='Historical FY16-FY25'!A16 -> Botetourt County | B17: ='Historical FY16-FY25'!B16 -> County | C17: ='Historical FY16-FY25'!D16 -> 4739530 | D17: ='Projection FY26-FY45'!D16 -> 0.042534743 | E17: =$C17*(Assumptions!$B$28/Assumptions!$B$29)*(1+$D17)^2 -> 5151294.2 | F17: =$C17*(Assumptions!$B$28/Assumptions!$B$29)*(1+$D17)^10 -> 7188539.2 | G17: =$C17*(Assumptions!$B$28/Assumptions!$B$29)*(1+$D17)^20 -> 10903000 | H17: =IF($D17=0,$C17*(Assumptions!$B$28/Assumptions!$B$29)*20,$C17*(Assumptions!$B$28/Assumptions!$B$29)*(1+$D17)*((1+$D17)^20-1)/$D17) -> 1.5106784e+08 | I17: =H17/20 -> 7553391.9 | J17: =IFERROR(H17/$H$139,0) -> 0.0024615403 | K17: ='Projection FY26-FY45'!E16*0.01 -> 108985.16
... A138: ='Historical FY16-FY25'!A137 -> Winchester City | B138: ='Historical FY16-FY25'!B137 -> City | C138: ='Historical FY16-FY25'!D137 -> 13385081 | D138: ='Projection FY26-FY45'!D137 -> 0.042714733 | E138: =$C138*(Assumptions!$B$28/Assumptions!$B$29)*(1+$D138)^2 -> 14552983 | F138: =$C138*(Assumptions!$B$28/Assumptions!$B$29)*(1+$D138)^10 -> 20336495 | G138: =$C138*(Assumptions!$B$28/Assumptions!$B$29)*(1+$D138)^20 -> 30898059 | H138: =IF($D138=0,$C138*(Assumptions!$B$28/Assumptions!$B$29)*20,$C138*(Assumptions!$B$28/Assumptions!$B$29)*(1+$D138)*((1+$D138)^20-1)/$D138) -> 4.2751152e+08 | I138: =H138/20 -> 21375576 | J138: =IFERROR(H138/$H$139,0) -> 0.0069659886 | K138: ='Projection FY26-FY45'!E137*0.01 -> 190401.8
A139: TOTAL — all localities | C139: =SUM(C6:C138) -> 1876912593 | E139: =SUM(E6:E138) -> 2.0481156e+09 | F139: =SUM(F6:F138) -> 2.9067944e+09 | G139: =SUM(G6:G138) -> 4.512886e+09 | H139: =SUM(H6:H138) -> 6.1371263e+10 | I139: =SUM(I6:I138) -> 3.0685632e+09 | J139: =SUM(J6:J138) -> 1 | K139: =SUM(K6:K138) -> 35948234
A141: How to read this tab for one locality: column E is roughly what the first full year of a new 1% school levy would
A142: raise there; column H is what it would raise across the whole 20-year window; column I is the level annual figure a
A143: bond-capacity conversation would start from. Column K is the far smaller 'set aside 1% of revenue' reading.
A144: Assumption: the school levy has the same tax base as the existing local option. Check current statute — some
A145: formulations exempt food and essential personal hygiene products, which would reduce these figures materially.
A146: A new levy requires enabling authority and, in Virginia, a local referendum. These are revenue estimates only.

Sheet Opportunity Controls
A1: Opportunity Model — Controls
A2: Everything on the Opportunity Model tab is driven from here. Yellow cells are yours to change.
A4: Access multipliers by status
A5: Status | B5: Multiplier | C5: What it means
A6: On Nov 2026 ballot | B6: 1 | C6: Referendum filed for the Nov 3, 2026 ballot. Funding decision imminent; procurement follows in 2027.
A7: Deferred, eyeing 2027 | B7: 0.8 | C7: Publicly discussed and deferred, generally to a 2027 referendum. Known intent, longer cycle.
A8: No public action found | B8: 0.7 | C8: Nothing found in reporting. UNVERIFIED, not confirmed inactive — many of these have almost certainly filed.
A9: Levying since 2020-23 | B9: =IF($B$12="Yes",$B$13,1) -> 0.35 | C9: Levying since 2020-23 under the original nine-locality authority. Capital programme already underway.
A11: Model levers
A12: Treat already-levying localities as exhausted? | B12: Yes | C12: Yes or No. Your original question said "if previous opportunities have not been exhausted" — Yes reflects that.
A13: ...if Yes, multiplier applied to them | B13: 0.35 | C13: 0 would remove them from contention entirely; 1 would treat prior adoption as no disadvantage.
A14: Capacity compression exponent | B14: 0.38 | C14: 1.00 = raw dollars, so Fairfax swamps everything. Lower values pull mid-size localities into view. 0.38 is the default.
A15: Minimum FY2027 yield to shortlist ($) | B15: 3000000 | C15: Used by the Shortlist flag. Below this, a standalone performance contract is unlikely to pencil.
A16: Scope: Counties, Cities, or Both | B16: Counties | C16: Controls which rows are ranked and which feed the Region Summary. Type one of the three words exactly.
A18: Where the status flags came from
A19: Levying since 2020-23 — Virginia Tax FY2025 Annual Report, Table 4.1 note 15. Eight localities. Solid.
A20: On Nov 2026 ballot / Deferred — only the localities named individually in reporting through 10 Aug 2026.
A21: That is 16 confirmed of the 40+ that had filed as of 7 Aug. The rest sit in 'No public action found'.
A22: The 2026-28 state budget opened Va. Code 58.1-605.1 to every county and city, effective 1 July 2026.
A23: Filing deadline for the 3 Nov 2026 ballot was 14 Aug 2026 — the authoritative list settles after that.
A24: ACTION: pull the Department of Elections referendum filings and update the Status column. Everything recalculates.
A26: What this model does not know
A27: This ranks FUNDING CAPACITY, not facility need. It carries no building age, no deferred-maintenance
A28: backlog, no existing ESCO contracts and no current energy spend — the things that decide whether a
A29: performance contract actually pencils. Layer in VDOE's school building needs and conditions survey and
A30: the list of divisions already under state energy performance contracts before this drives a call plan.

Sheet Opportunity Model
A1: Performance Contracting Opportunity — Virginia Localities
A2: Heat = opportunity score: 20-year capacity of a 1% school levy, discounted by how far the locality has already used the option. Edit the Status column as referendum filings are confirmed.
A3: Colour bands are septiles of the localities currently IN SCOPE, so the ramp always spans the full set — a red row is top-seventh of what's ranked, not an absolute threshold.
A5: Locality | B5: Type | C5: Region | D5: Status (edit me) | E5: In scope | F5: FY2027 levy yield ($) | G5: 20-yr capacity ($) | H5: Capacity index | I5: Access multiplier | J5: Opportunity score | K5: Rank | L5: Septile | M5: Priority | N5: Shortlist | O5: Score (numeric helper)
A6: ='Historical FY16-FY25'!A5 -> Accomack County | B6: ='Historical FY16-FY25'!B5 -> County | C6: Eastern Shore | D6: No public action found | E6: =IF(OR('Opportunity Controls'!$B$16="Both",AND('Opportunity Controls'!$B$16="Counties",$B6="County"),AND('Opportunity Controls'!$B$16="Cities",$B6="City")),1,0) -> 1 | F6: ='Schools 1pct Profile'!E6 -> 6888381.4 | G6: ='Schools 1pct Profile'!H6 -> 1.9629732e+08 | H6: =IFERROR(($G6/MAX($G$6:$G$138))^'Opportunity Controls'!$B$14*100,0) -> 24.609716 | I6: =IFERROR(INDEX('Opportunity Controls'!$B$6:$B$9,MATCH($D6,'Opportunity Controls'!$A$6:$A$9,0)),1) -> 0.7 | J6: =IF($E6=0,"",$H6*$I6) -> 17.226801 | K6: =IF($E6=0,"",RANK($J6,$J$6:$J$138)) -> 38 | L6: =IF($E6=0,"",8-ROUNDUP($K6/COUNT($J$6:$J$138)*7,0)) -> 5 | M6: =IF($E6=0,"",IF($L6>=6,"Priority 1",IF($L6>=5,"Priority 2",IF($L6>=3,"Watch","Low")))) -> Priority 2 | N6: =IF($E6=0,"",IF(AND($F6>='Opportunity Controls'!$B$15,$L6>=6),"YES","")) | O6: =IF($E6=0,0,$H6*$I6) -> 17.226801
A7: ='Historical FY16-FY25'!A6 -> Albemarle County | B7: ='Historical FY16-FY25'!B6 -> County | C7: Central Piedmont | D7: No public action found | E7: =IF(OR('Opportunity Controls'!$B$16="Both",AND('Opportunity Controls'!$B$16="Counties",$B7="County"),AND('Opportunity Controls'!$B$16="Cities",$B7="City")),1,0) -> 1 | F7: ='Schools 1pct Profile'!E7 -> 28874529 | G7: ='Schools 1pct Profile'!H7 -> 9.0317202e+08 | H7: =IFERROR(($G7/MAX($G$6:$G$138))^'Opportunity Controls'!$B$14*100,0) -> 43.953344 | I7: =IFERROR(INDEX('Opportunity Controls'!$B$6:$B$9,MATCH($D7,'Opportunity Controls'!$A$6:$A$9,0)),1) -> 0.7 | J7: =IF($E7=0,"",$H7*$I7) -> 30.767341 | K7: =IF($E7=0,"",RANK($J7,$J$6:$J$138)) -> 10 | L7: =IF($E7=0,"",8-ROUNDUP($K7/COUNT($J$6:$J$138)*7,0)) -> 7 | M7: =IF($E7=0,"",IF($L7>=6,"Priority 1",IF($L7>=5,"Priority 2",IF($L7>=3,"Watch","Low")))) -> Priority 1 | N7: =IF($E7=0,"",IF(AND($F7>='Opportunity Controls'!$B$15,$L7>=6),"YES","")) -> YES | O7: =IF($E7=0,0,$H7*$I7) -> 30.767341
A8: ='Historical FY16-FY25'!A7 -> Alleghany County | B8: ='Historical FY16-FY25'!B7 -> County | C8: Shenandoah Valley & Alleghany | D8: No public action found | E8: =IF(OR('Opportunity Controls'!$B$16="Both",AND('Opportunity Controls'!$B$16="Counties",$B8="County"),AND('Opportunity Controls'!$B$16="Cities",$B8="City")),1,0) -> 1 | F8: ='Schools 1pct Profile'!E8 -> 1368536.1 | G8: ='Schools 1pct Profile'!H8 -> 35851158 | H8: =IFERROR(($G8/MAX($G$6:$G$138))^'Opportunity Controls'!$B$14*100,0) -> 12.897643 | I8: =IFERROR(INDEX('Opportunity Controls'!$B$6:$B$9,MATCH($D8,'Opportunity Controls'!$A$6:$A$9,0)),1) -> 0.7 | J8: =IF($E8=0,"",$H8*$I8) -> 9.02835 | K8: =IF($E8=0,"",RANK($J8,$J$6:$J$138)) -> 80 | L8: =IF($E8=0,"",8-ROUNDUP($K8/COUNT($J$6:$J$138)*7,0)) -> 2 | M8: =IF($E8=0,"",IF($L8>=6,"Priority 1",IF($L8>=5,"Priority 2",IF($L8>=3,"Watch","Low")))) -> Low | N8: =IF($E8=0,"",IF(AND($F8>='Opportunity Controls'!$B$15,$L8>=6),"YES","")) | O8: =IF($E8=0,0,$H8*$I8) -> 9.02835
A9: ='Historical FY16-FY25'!A8 -> Amelia County | B9: ='Historical FY16-FY25'!B8 -> County | C9: Richmond Metro | D9: No public action found | E9: =IF(OR('Opportunity Controls'!$B$16="Both",AND('Opportunity Controls'!$B$16="Counties",$B9="County"),AND('Opportunity Controls'!$B$16="Cities",$B9="City")),1,0) -> 1 | F9: ='Schools 1pct Profile'!E9 -> 1663744.2 | G9: ='Schools 1pct Profile'!H9 -> 50578822 | H9: =IFERROR(($G9/MAX($G$6:$G$138))^'Opportunity Controls'!$B$14*100,0) -> 14.699659 | I9: =IFERROR(INDEX('Opportunity Controls'!$B$6:$B$9,MATCH($D9,'Opportunity Controls'!$A$6:$A$9,0)),1) -> 0.7 | J9: =IF($E9=0,"",$H9*$I9) -> 10.289761 | K9: =IF($E9=0,"",RANK($J9,$J$6:$J$138)) -> 69 | L9: =IF($E9=0,"",8-ROUNDUP($K9/COUNT($J$6:$J$138)*7,0)) -> 2 | M9: =IF($E9=0,"",IF($L9>=6,"Priority 1",IF($L9>=5,"Priority 2",IF($L9>=3,"Watch","Low")))) -> Low | N9: =IF($E9=0,"",IF(AND($F9>='Opportunity Controls'!$B$15,$L9>=6),"YES","")) | O9: =IF($E9=0,0,$H9*$I9) -> 10.289761
A10: ='Historical FY16-FY25'!A9 -> Amherst County | B10: ='Historical FY16-FY25'!B9 -> County | C10: Southside | D10: Deferred, eyeing 2027 | E10: =IF(OR('Opportunity Controls'!$B$16="Both",AND('Opportunity Controls'!$B$16="Counties",$B10="County"),AND('Opportunity Controls'!$B$16="Cities",$B10="City")),1,0) -> 1 | F10: ='Schools 1pct Profile'!E10 -> 5156295.1 | G10: ='Schools 1pct Profile'!H10 -> 1.5398921e+08 | H10: =IFERROR(($G10/MAX($G$6:$G$138))^'Opportunity Controls'!$B$14*100,0) -> 22.441168 | I10: =IFERROR(INDEX('Opportunity Controls'!$B$6:$B$9,MATCH($D10,'Opportunity Controls'!$A$6:$A$9,0)),1) -> 0.8 | J10: =IF($E10=0,"",$H10*$I10) -> 17.952934 | K10: =IF($E10=0,"",RANK($J10,$J$6:$J$138)) -> 37 | L10: =IF($E10=0,"",8-ROUNDUP($K10/COUNT($J$6:$J$138)*7,0)) -> 5 | M10: =IF($E10=0,"",IF($L10>=6,"Priority 1",IF($L10>=5,"Priority 2",IF($L10>=3,"Watch","Low")))) -> Priority 2 | N10: =IF($E10=0,"",IF(AND($F10>='Opportunity Controls'!$B$15,$L10>=6),"YES","")) | O10: =IF($E10=0,0,$H10*$I10) -> 17.952934
A11: ='Historical FY16-FY25'!A10 -> Appomattox County | B11: ='Historical FY16-FY25'!B10 -> County | C11: Southside | D11: No public action found | E11: =IF(OR('Opportunity Controls'!$B$16="Both",AND('Opportunity Controls'!$B$16="Counties",$B11="County"),AND('Opportunity Controls'!$B$16="Cities",$B11="City")),1,0) -> 1 | F11: ='Schools 1pct Profile'!E11 -> 2407487.2 | G11: ='Schools 1pct Profile'!H11 -> 74351620 | H11: =IFERROR(($G11/MAX($G$6:$G$138))^'Opportunity Controls'!$B$14*100,0) -> 17.017255 | I11: =IFERROR(INDEX('Opportunity Controls'!$B$6:$B$9,MATCH($D11,'Opportunity Controls'!$A$6:$A$9,0)),1) -> 0.7 | J11: =IF($E11=0,"",$H11*$I11) -> 11.912078 | K11: =IF($E11=0,"",RANK($J11,$J$6:$J$138)) -> 61 | L11: =IF($E11=0,"",8-ROUNDUP($K11/COUNT($J$6:$J$138)*7,0)) -> 3 | M11: =IF($E11=0,"",IF($L11>=6,"Priority 1",IF($L11>=5,"Priority 2",IF($L11>=3,"Watch","Low")))) -> Watch | N11: =IF($E11=0,"",IF(AND($F11>='Opportunity Controls'!$B$15,$L11>=6),"YES","")) | O11: =IF($E11=0,0,$H11*$I11) -> 11.912078
